[2023-12-26T08:06:22.545+0000] {taskinstance.py:1159} INFO - Dependencies all met for dep_context=non-requeueable deps ti=<TaskInstance: dd_mssql_snapshot.generate_date_strings manual__2023-12-26T08:06:21.468121+00:00 [queued]>
[2023-12-26T08:06:22.553+0000] {taskinstance.py:1159} INFO - Dependencies all met for dep_context=requeueable deps ti=<TaskInstance: dd_mssql_snapshot.generate_date_strings manual__2023-12-26T08:06:21.468121+00:00 [queued]>
[2023-12-26T08:06:22.554+0000] {taskinstance.py:1361} INFO - Starting attempt 1 of 2
[2023-12-26T08:06:22.562+0000] {taskinstance.py:1382} INFO - Executing <Task(_PythonDecoratedOperator): generate_date_strings> on 2023-12-26 08:06:21.468121+00:00
[2023-12-26T08:06:22.567+0000] {standard_task_runner.py:57} INFO - Started process 2721 to run task
[2023-12-26T08:06:22.575+0000] {standard_task_runner.py:84} INFO - Running: ['***', 'tasks', 'run', 'dd_mssql_snapshot', 'generate_date_strings', 'manual__2023-12-26T08:06:21.468121+00:00', '--job-id', '33', '--raw', '--subdir', 'DAGS_FOLDER/test-date.py', '--cfg-path', '/tmp/tmpc4dryu7l']
[2023-12-26T08:06:22.577+0000] {standard_task_runner.py:85} INFO - Job 33: Subtask generate_date_strings
[2023-12-26T08:06:22.642+0000] {task_command.py:416} INFO - Running <TaskInstance: dd_mssql_snapshot.generate_date_strings manual__2023-12-26T08:06:21.468121+00:00 [running]> on host 5837c4e7e133
[2023-12-26T08:06:22.724+0000] {taskinstance.py:1662} INFO - Exporting env vars: AIRFLOW_CTX_DAG_OWNER='***' AIRFLOW_CTX_DAG_ID='dd_mssql_snapshot' AIRFLOW_CTX_TASK_ID='generate_date_strings' AIRFLOW_CTX_EXECUTION_DATE='2023-12-26T08:06:21.468121+00:00' AIRFLOW_CTX_TRY_NUMBER='1' AIRFLOW_CTX_DAG_RUN_ID='manual__2023-12-26T08:06:21.468121+00:00'
[2023-12-26T08:06:22.734+0000] {taskinstance.py:1937} ERROR - Task failed with exception
Traceback (most recent call last):
  File "/home/airflow/.local/lib/python3.8/site-packages/airflow/decorators/base.py", line 221, in execute
    return_value = super().execute(context)
  File "/home/airflow/.local/lib/python3.8/site-packages/airflow/operators/python.py", line 192, in execute
    return_value = self.execute_callable()
  File "/home/airflow/.local/lib/python3.8/site-packages/airflow/operators/python.py", line 209, in execute_callable
    return self.python_callable(*self.op_args, **self.op_kwargs)
  File "/opt/airflow/dags/test-date.py", line 39, in generate_date_strings
    current_time = get_date(previous=1, next=2, delta=None, timezone="Asia/Kuala_Lumpur")
TypeError: get_date() missing 1 required positional argument: 'self'
[2023-12-26T08:06:22.768+0000] {taskinstance.py:1400} INFO - Marking task as UP_FOR_RETRY. dag_id=dd_mssql_snapshot, task_id=generate_date_strings, execution_date=20231226T080621, start_date=20231226T080622, end_date=20231226T080622
[2023-12-26T08:06:22.793+0000] {standard_task_runner.py:104} ERROR - Failed to execute job 33 for task generate_date_strings (get_date() missing 1 required positional argument: 'self'; 2721)
[2023-12-26T08:06:22.838+0000] {local_task_job_runner.py:228} INFO - Task exited with return code 1
[2023-12-26T08:06:22.853+0000] {taskinstance.py:2778} INFO - 0 downstream tasks scheduled from follow-on schedule check
