[2024-05-22T13:59:09.705+0000] {taskinstance.py:1159} INFO - Dependencies all met for dep_context=non-requeueable deps ti=<TaskInstance: fraud_bitcoin.push_github_task manual__2024-05-22T01:43:43.000580+00:00 [queued]>
[2024-05-22T13:59:09.712+0000] {taskinstance.py:1159} INFO - Dependencies all met for dep_context=requeueable deps ti=<TaskInstance: fraud_bitcoin.push_github_task manual__2024-05-22T01:43:43.000580+00:00 [queued]>
[2024-05-22T13:59:09.713+0000] {taskinstance.py:1361} INFO - Starting attempt 7 of 8
[2024-05-22T13:59:09.728+0000] {taskinstance.py:1382} INFO - Executing <Task(PythonOperator): push_github_task> on 2024-05-22 01:43:43.000580+00:00
[2024-05-22T13:59:09.738+0000] {standard_task_runner.py:57} INFO - Started process 2517 to run task
[2024-05-22T13:59:09.741+0000] {standard_task_runner.py:84} INFO - Running: ['***', 'tasks', 'run', 'fraud_bitcoin', 'push_github_task', 'manual__2024-05-22T01:43:43.000580+00:00', '--job-id', '444', '--raw', '--subdir', 'DAGS_FOLDER/fraud.py', '--cfg-path', '/tmp/tmp1x0ouvfq']
[2024-05-22T13:59:09.745+0000] {standard_task_runner.py:85} INFO - Job 444: Subtask push_github_task
[2024-05-22T13:59:09.801+0000] {task_command.py:416} INFO - Running <TaskInstance: fraud_bitcoin.push_github_task manual__2024-05-22T01:43:43.000580+00:00 [running]> on host 73682f8f7a2b
[2024-05-22T13:59:09.868+0000] {taskinstance.py:1662} INFO - Exporting env vars: AIRFLOW_CTX_DAG_OWNER='***' AIRFLOW_CTX_DAG_ID='fraud_bitcoin' AIRFLOW_CTX_TASK_ID='push_github_task' AIRFLOW_CTX_EXECUTION_DATE='2024-05-22T01:43:43.000580+00:00' AIRFLOW_CTX_TRY_NUMBER='7' AIRFLOW_CTX_DAG_RUN_ID='manual__2024-05-22T01:43:43.000580+00:00'
[2024-05-22T13:59:11.741+0000] {taskinstance.py:1937} ERROR - Task failed with exception
Traceback (most recent call last):
  File "/home/airflow/.local/lib/python3.8/site-packages/airflow/operators/python.py", line 192, in execute
    return_value = self.execute_callable()
  File "/home/airflow/.local/lib/python3.8/site-packages/airflow/operators/python.py", line 209, in execute_callable
    return self.python_callable(*self.op_args, **self.op_kwargs)
  File "/opt/airflow/dags/fraud.py", line 350, in push_to_github
    shutil.copy(model_path, dest_model_path)
  File "/usr/local/lib/python3.8/shutil.py", line 418, in copy
    copyfile(src, dst, follow_symlinks=follow_symlinks)
  File "/usr/local/lib/python3.8/shutil.py", line 264, in copyfile
    with open(src, 'rb') as fsrc, open(dst, 'wb') as fdst:
PermissionError: [Errno 13] Permission denied: '/best_model.pkl'
[2024-05-22T13:59:11.784+0000] {taskinstance.py:1400} INFO - Marking task as UP_FOR_RETRY. dag_id=fraud_bitcoin, task_id=push_github_task, execution_date=20240522T014343, start_date=20240522T135909, end_date=20240522T135911
[2024-05-22T13:59:11.808+0000] {standard_task_runner.py:104} ERROR - Failed to execute job 444 for task push_github_task ([Errno 13] Permission denied: '/best_model.pkl'; 2517)
[2024-05-22T13:59:11.871+0000] {local_task_job_runner.py:228} INFO - Task exited with return code 1
[2024-05-22T13:59:11.938+0000] {taskinstance.py:2778} INFO - 0 downstream tasks scheduled from follow-on schedule check
