[2024-05-22T14:50:12.785+0000] {taskinstance.py:1159} INFO - Dependencies all met for dep_context=non-requeueable deps ti=<TaskInstance: fraud_bitcoin.push_github_task manual__2024-05-22T01:43:43.000580+00:00 [queued]>
[2024-05-22T14:50:12.796+0000] {taskinstance.py:1159} INFO - Dependencies all met for dep_context=requeueable deps ti=<TaskInstance: fraud_bitcoin.push_github_task manual__2024-05-22T01:43:43.000580+00:00 [queued]>
[2024-05-22T14:50:12.797+0000] {taskinstance.py:1361} INFO - Starting attempt 16 of 16
[2024-05-22T14:50:12.813+0000] {taskinstance.py:1382} INFO - Executing <Task(PythonOperator): push_github_task> on 2024-05-22 01:43:43.000580+00:00
[2024-05-22T14:50:12.824+0000] {standard_task_runner.py:57} INFO - Started process 3047 to run task
[2024-05-22T14:50:12.844+0000] {standard_task_runner.py:84} INFO - Running: ['***', 'tasks', 'run', 'fraud_bitcoin', 'push_github_task', 'manual__2024-05-22T01:43:43.000580+00:00', '--job-id', '453', '--raw', '--subdir', 'DAGS_FOLDER/fraud.py', '--cfg-path', '/tmp/tmpoj7wc407']
[2024-05-22T14:50:12.858+0000] {standard_task_runner.py:85} INFO - Job 453: Subtask push_github_task
[2024-05-22T14:50:12.966+0000] {task_command.py:416} INFO - Running <TaskInstance: fraud_bitcoin.push_github_task manual__2024-05-22T01:43:43.000580+00:00 [running]> on host 73682f8f7a2b
[2024-05-22T14:50:13.061+0000] {taskinstance.py:1662} INFO - Exporting env vars: AIRFLOW_CTX_DAG_OWNER='***' AIRFLOW_CTX_DAG_ID='fraud_bitcoin' AIRFLOW_CTX_TASK_ID='push_github_task' AIRFLOW_CTX_EXECUTION_DATE='2024-05-22T01:43:43.000580+00:00' AIRFLOW_CTX_TRY_NUMBER='16' AIRFLOW_CTX_DAG_RUN_ID='manual__2024-05-22T01:43:43.000580+00:00'
[2024-05-22T14:50:14.466+0000] {taskinstance.py:1937} ERROR - Task failed with exception
Traceback (most recent call last):
  File "/home/airflow/.local/lib/python3.8/site-packages/airflow/operators/python.py", line 192, in execute
    return_value = self.execute_callable()
  File "/home/airflow/.local/lib/python3.8/site-packages/airflow/operators/python.py", line 209, in execute_callable
    return self.python_callable(*self.op_args, **self.op_kwargs)
  File "/opt/airflow/dags/fraud.py", line 356, in push_to_github
    os.chmod(dest_model_path, stat.S_IWUSR | stat.S_IWGRP | stat.S_IWOTH)
FileNotFoundError: [Errno 2] No such file or directory: '/best_model.pkl'
[2024-05-22T14:50:14.501+0000] {taskinstance.py:1400} INFO - Marking task as FAILED. dag_id=fraud_bitcoin, task_id=push_github_task, execution_date=20240522T014343, start_date=20240522T145012, end_date=20240522T145014
[2024-05-22T15:37:59.908+0000] {standard_task_runner.py:104} ERROR - Failed to execute job 453 for task push_github_task ([Errno 2] No such file or directory: '/best_model.pkl'; 3047)
[2024-05-22T15:37:59.964+0000] {local_task_job_runner.py:228} INFO - Task exited with return code 1
[2024-05-22T15:38:00.022+0000] {taskinstance.py:2778} INFO - 0 downstream tasks scheduled from follow-on schedule check
