[2024-05-22T02:33:46.926+0000] {taskinstance.py:1159} INFO - Dependencies all met for dep_context=non-requeueable deps ti=<TaskInstance: fraud_bitcoin.push_github_task manual__2024-05-22T01:43:43.000580+00:00 [queued]>
[2024-05-22T02:33:46.932+0000] {taskinstance.py:1159} INFO - Dependencies all met for dep_context=requeueable deps ti=<TaskInstance: fraud_bitcoin.push_github_task manual__2024-05-22T01:43:43.000580+00:00 [queued]>
[2024-05-22T02:33:46.932+0000] {taskinstance.py:1361} INFO - Starting attempt 3 of 3
[2024-05-22T02:33:46.940+0000] {taskinstance.py:1382} INFO - Executing <Task(PythonOperator): push_github_task> on 2024-05-22 01:43:43.000580+00:00
[2024-05-22T02:33:46.950+0000] {standard_task_runner.py:57} INFO - Started process 283 to run task
[2024-05-22T02:33:46.953+0000] {standard_task_runner.py:84} INFO - Running: ['***', 'tasks', 'run', 'fraud_bitcoin', 'push_github_task', 'manual__2024-05-22T01:43:43.000580+00:00', '--job-id', '438', '--raw', '--subdir', 'DAGS_FOLDER/fraud.py', '--cfg-path', '/tmp/tmpdidcyp06']
[2024-05-22T02:33:46.958+0000] {standard_task_runner.py:85} INFO - Job 438: Subtask push_github_task
[2024-05-22T02:33:47.003+0000] {task_command.py:416} INFO - Running <TaskInstance: fraud_bitcoin.push_github_task manual__2024-05-22T01:43:43.000580+00:00 [running]> on host cda76daf7a15
[2024-05-22T02:33:47.082+0000] {taskinstance.py:1662} INFO - Exporting env vars: AIRFLOW_CTX_DAG_OWNER='***' AIRFLOW_CTX_DAG_ID='fraud_bitcoin' AIRFLOW_CTX_TASK_ID='push_github_task' AIRFLOW_CTX_EXECUTION_DATE='2024-05-22T01:43:43.000580+00:00' AIRFLOW_CTX_TRY_NUMBER='3' AIRFLOW_CTX_DAG_RUN_ID='manual__2024-05-22T01:43:43.000580+00:00'
[2024-05-22T02:33:48.473+0000] {taskinstance.py:1937} ERROR - Task failed with exception
Traceback (most recent call last):
  File "/home/airflow/.local/lib/python3.8/site-packages/airflow/operators/python.py", line 192, in execute
    return_value = self.execute_callable()
  File "/home/airflow/.local/lib/python3.8/site-packages/airflow/operators/python.py", line 209, in execute_callable
    return self.python_callable(*self.op_args, **self.op_kwargs)
  File "/opt/airflow/dags/fraud.py", line 350, in push_to_github
    shutil.copy(model_path, dest_model_path)
  File "/usr/local/lib/python3.8/shutil.py", line 418, in copy
    copyfile(src, dst, follow_symlinks=follow_symlinks)
  File "/usr/local/lib/python3.8/shutil.py", line 264, in copyfile
    with open(src, 'rb') as fsrc, open(dst, 'wb') as fdst:
PermissionError: [Errno 13] Permission denied: '/best_model.pkl'
[2024-05-22T02:33:48.491+0000] {taskinstance.py:1400} INFO - Marking task as FAILED. dag_id=fraud_bitcoin, task_id=push_github_task, execution_date=20240522T014343, start_date=20240522T023346, end_date=20240522T023348
[2024-05-22T02:33:48.502+0000] {standard_task_runner.py:104} ERROR - Failed to execute job 438 for task push_github_task ([Errno 13] Permission denied: '/best_model.pkl'; 283)
[2024-05-22T02:33:48.541+0000] {local_task_job_runner.py:228} INFO - Task exited with return code 1
[2024-05-22T02:33:48.558+0000] {taskinstance.py:2778} INFO - 0 downstream tasks scheduled from follow-on schedule check
