[2024-05-22T13:58:45.780+0000] {taskinstance.py:1159} INFO - Dependencies all met for dep_context=non-requeueable deps ti=<TaskInstance: fraud_bitcoin.push_github_task manual__2024-05-22T01:43:43.000580+00:00 [queued]>
[2024-05-22T13:58:45.786+0000] {taskinstance.py:1159} INFO - Dependencies all met for dep_context=requeueable deps ti=<TaskInstance: fraud_bitcoin.push_github_task manual__2024-05-22T01:43:43.000580+00:00 [queued]>
[2024-05-22T13:58:45.787+0000] {taskinstance.py:1361} INFO - Starting attempt 6 of 7
[2024-05-22T13:58:45.794+0000] {taskinstance.py:1382} INFO - Executing <Task(PythonOperator): push_github_task> on 2024-05-22 01:43:43.000580+00:00
[2024-05-22T13:58:45.801+0000] {standard_task_runner.py:57} INFO - Started process 2493 to run task
[2024-05-22T13:58:45.805+0000] {standard_task_runner.py:84} INFO - Running: ['***', 'tasks', 'run', 'fraud_bitcoin', 'push_github_task', 'manual__2024-05-22T01:43:43.000580+00:00', '--job-id', '443', '--raw', '--subdir', 'DAGS_FOLDER/fraud.py', '--cfg-path', '/tmp/tmpq5l3sf35']
[2024-05-22T13:58:45.808+0000] {standard_task_runner.py:85} INFO - Job 443: Subtask push_github_task
[2024-05-22T13:58:45.852+0000] {task_command.py:416} INFO - Running <TaskInstance: fraud_bitcoin.push_github_task manual__2024-05-22T01:43:43.000580+00:00 [running]> on host 73682f8f7a2b
[2024-05-22T13:58:45.912+0000] {taskinstance.py:1662} INFO - Exporting env vars: AIRFLOW_CTX_DAG_OWNER='***' AIRFLOW_CTX_DAG_ID='fraud_bitcoin' AIRFLOW_CTX_TASK_ID='push_github_task' AIRFLOW_CTX_EXECUTION_DATE='2024-05-22T01:43:43.000580+00:00' AIRFLOW_CTX_TRY_NUMBER='6' AIRFLOW_CTX_DAG_RUN_ID='manual__2024-05-22T01:43:43.000580+00:00'
[2024-05-22T13:58:47.902+0000] {taskinstance.py:1937} ERROR - Task failed with exception
Traceback (most recent call last):
  File "/home/airflow/.local/lib/python3.8/site-packages/airflow/operators/python.py", line 192, in execute
    return_value = self.execute_callable()
  File "/home/airflow/.local/lib/python3.8/site-packages/airflow/operators/python.py", line 209, in execute_callable
    return self.python_callable(*self.op_args, **self.op_kwargs)
  File "/opt/airflow/dags/fraud.py", line 346, in push_to_github
    os.chmod(os.path.join(repo_dir, 'best_model.pkl'), 0o775)
FileNotFoundError: [Errno 2] No such file or directory: '/tmp/bitcoin-fraud-detection/saved_model/best_model.pkl'
[2024-05-22T13:58:47.945+0000] {taskinstance.py:1400} INFO - Marking task as UP_FOR_RETRY. dag_id=fraud_bitcoin, task_id=push_github_task, execution_date=20240522T014343, start_date=20240522T135845, end_date=20240522T135847
[2024-05-22T13:58:47.970+0000] {standard_task_runner.py:104} ERROR - Failed to execute job 443 for task push_github_task ([Errno 2] No such file or directory: '/tmp/bitcoin-fraud-detection/saved_model/best_model.pkl'; 2493)
[2024-05-22T13:58:48.035+0000] {local_task_job_runner.py:228} INFO - Task exited with return code 1
[2024-05-22T13:58:48.089+0000] {taskinstance.py:2778} INFO - 0 downstream tasks scheduled from follow-on schedule check
