[2024-05-22T00:10:27.940+0000] {taskinstance.py:1159} INFO - Dependencies all met for dep_context=non-requeueable deps ti=<TaskInstance: fraud_bitcoin.train_deep_learning scheduled__2024-05-21T00:00:00+00:00 [queued]>
[2024-05-22T00:10:27.995+0000] {taskinstance.py:1159} INFO - Dependencies all met for dep_context=requeueable deps ti=<TaskInstance: fraud_bitcoin.train_deep_learning scheduled__2024-05-21T00:00:00+00:00 [queued]>
[2024-05-22T00:10:27.998+0000] {taskinstance.py:1361} INFO - Starting attempt 1 of 2
[2024-05-22T00:10:28.046+0000] {taskinstance.py:1382} INFO - Executing <Task(PythonOperator): train_deep_learning> on 2024-05-21 00:00:00+00:00
[2024-05-22T00:10:28.164+0000] {standard_task_runner.py:57} INFO - Started process 3643 to run task
[2024-05-22T00:10:28.210+0000] {standard_task_runner.py:84} INFO - Running: ['***', 'tasks', 'run', 'fraud_bitcoin', 'train_deep_learning', 'scheduled__2024-05-21T00:00:00+00:00', '--job-id', '375', '--raw', '--subdir', 'DAGS_FOLDER/fraud.py', '--cfg-path', '/tmp/tmpf38w9x3f']
[2024-05-22T00:10:28.268+0000] {standard_task_runner.py:85} INFO - Job 375: Subtask train_deep_learning
[2024-05-22T00:10:28.675+0000] {task_command.py:416} INFO - Running <TaskInstance: fraud_bitcoin.train_deep_learning scheduled__2024-05-21T00:00:00+00:00 [running]> on host 66abfe055500
[2024-05-22T00:10:29.215+0000] {taskinstance.py:1662} INFO - Exporting env vars: AIRFLOW_CTX_DAG_OWNER='***' AIRFLOW_CTX_DAG_ID='fraud_bitcoin' AIRFLOW_CTX_TASK_ID='train_deep_learning' AIRFLOW_CTX_EXECUTION_DATE='2024-05-21T00:00:00+00:00' AIRFLOW_CTX_TRY_NUMBER='1' AIRFLOW_CTX_DAG_RUN_ID='scheduled__2024-05-21T00:00:00+00:00'
[2024-05-22T00:10:29.773+0000] {taskinstance.py:1937} ERROR - Task failed with exception
Traceback (most recent call last):
  File "/home/airflow/.local/lib/python3.8/site-packages/airflow/operators/python.py", line 192, in execute
    return_value = self.execute_callable()
  File "/home/airflow/.local/lib/python3.8/site-packages/airflow/operators/python.py", line 209, in execute_callable
    return self.python_callable(*self.op_args, **self.op_kwargs)
  File "/opt/airflow/dags/fraud.py", line 151, in train_deep_learning
    dl_model.fit(X_significant_train, y_train_categorical)
  File "/home/airflow/.local/lib/python3.8/site-packages/scikeras/wrappers.py", line 1491, in fit
    super().fit(X=X, y=y, sample_weight=sample_weight, **kwargs)
  File "/home/airflow/.local/lib/python3.8/site-packages/scikeras/wrappers.py", line 760, in fit
    self._fit(
  File "/home/airflow/.local/lib/python3.8/site-packages/scikeras/wrappers.py", line 915, in _fit
    X, y = self._initialize(X, y)
  File "/home/airflow/.local/lib/python3.8/site-packages/scikeras/wrappers.py", line 843, in _initialize
    X, y = self._validate_data(X, y, reset=True)
  File "/home/airflow/.local/lib/python3.8/site-packages/scikeras/wrappers.py", line 616, in _validate_data
    X, y = check_X_y(
  File "/home/airflow/.local/lib/python3.8/site-packages/sklearn/utils/validation.py", line 1146, in check_X_y
    X = check_array(
  File "/home/airflow/.local/lib/python3.8/site-packages/sklearn/utils/validation.py", line 976, in check_array
    raise ValueError(
ValueError: Found array with 0 feature(s) (shape=(944, 0)) while a minimum of 1 is required.
[2024-05-22T00:10:29.877+0000] {taskinstance.py:1400} INFO - Marking task as UP_FOR_RETRY. dag_id=fraud_bitcoin, task_id=train_deep_learning, execution_date=20240521T000000, start_date=20240522T001027, end_date=20240522T001029
[2024-05-22T00:10:29.968+0000] {standard_task_runner.py:104} ERROR - Failed to execute job 375 for task train_deep_learning (Found array with 0 feature(s) (shape=(944, 0)) while a minimum of 1 is required.; 3643)
[2024-05-22T00:10:30.121+0000] {local_task_job_runner.py:228} INFO - Task exited with return code 1
[2024-05-22T00:10:30.468+0000] {taskinstance.py:2778} INFO - 0 downstream tasks scheduled from follow-on schedule check
