[2024-04-28T17:19:23.450+0000] {taskinstance.py:1159} INFO - Dependencies all met for dep_context=non-requeueable deps ti=<TaskInstance: bitcoin_transaction_analysis.obtain_data manual__2024-04-28T17:19:22.055373+00:00 [queued]>
[2024-04-28T17:19:23.457+0000] {taskinstance.py:1159} INFO - Dependencies all met for dep_context=requeueable deps ti=<TaskInstance: bitcoin_transaction_analysis.obtain_data manual__2024-04-28T17:19:22.055373+00:00 [queued]>
[2024-04-28T17:19:23.457+0000] {taskinstance.py:1361} INFO - Starting attempt 1 of 2
[2024-04-28T17:19:23.468+0000] {taskinstance.py:1382} INFO - Executing <Task(PythonOperator): obtain_data> on 2024-04-28 17:19:22.055373+00:00
[2024-04-28T17:19:23.473+0000] {standard_task_runner.py:57} INFO - Started process 171 to run task
[2024-04-28T17:19:23.487+0000] {standard_task_runner.py:84} INFO - Running: ['***', 'tasks', 'run', 'bitcoin_transaction_analysis', 'obtain_data', 'manual__2024-04-28T17:19:22.055373+00:00', '--job-id', '136', '--raw', '--subdir', 'DAGS_FOLDER/bitcoin.py', '--cfg-path', '/tmp/tmp_rl5yj21']
[2024-04-28T17:19:23.523+0000] {standard_task_runner.py:85} INFO - Job 136: Subtask obtain_data
[2024-04-28T17:19:23.663+0000] {task_command.py:416} INFO - Running <TaskInstance: bitcoin_transaction_analysis.obtain_data manual__2024-04-28T17:19:22.055373+00:00 [running]> on host 93821e8db187
[2024-04-28T17:19:24.307+0000] {taskinstance.py:1662} INFO - Exporting env vars: AIRFLOW_CTX_DAG_OWNER='***' AIRFLOW_CTX_DAG_ID='bitcoin_transaction_analysis' AIRFLOW_CTX_TASK_ID='obtain_data' AIRFLOW_CTX_EXECUTION_DATE='2024-04-28T17:19:22.055373+00:00' AIRFLOW_CTX_TRY_NUMBER='1' AIRFLOW_CTX_DAG_RUN_ID='manual__2024-04-28T17:19:22.055373+00:00'
[2024-04-28T17:19:24.308+0000] {taskinstance.py:1937} ERROR - Task failed with exception
Traceback (most recent call last):
  File "/home/airflow/.local/lib/python3.8/site-packages/airflow/operators/python.py", line 192, in execute
    return_value = self.execute_callable()
  File "/home/airflow/.local/lib/python3.8/site-packages/airflow/operators/python.py", line 209, in execute_callable
    return self.python_callable(*self.op_args, **self.op_kwargs)
  File "/opt/airflow/dags/bitcoin.py", line 32, in obtain_data
    with zipfile.ZipFile('$DATASET_PATH/bitcoin.zip', 'r') as z:
  File "/usr/local/lib/python3.8/zipfile.py", line 1251, in __init__
    self.fp = io.open(file, filemode)
FileNotFoundError: [Errno 2] No such file or directory: '$DATASET_PATH/bitcoin.zip'
[2024-04-28T17:19:24.321+0000] {taskinstance.py:1400} INFO - Marking task as UP_FOR_RETRY. dag_id=bitcoin_transaction_analysis, task_id=obtain_data, execution_date=20240428T171922, start_date=20240428T171923, end_date=20240428T171924
[2024-04-28T17:19:24.333+0000] {standard_task_runner.py:104} ERROR - Failed to execute job 136 for task obtain_data ([Errno 2] No such file or directory: '$DATASET_PATH/bitcoin.zip'; 171)
[2024-04-28T17:19:24.344+0000] {local_task_job_runner.py:228} INFO - Task exited with return code 1
[2024-04-28T17:19:24.373+0000] {taskinstance.py:2778} INFO - 0 downstream tasks scheduled from follow-on schedule check
