[2024-04-28T17:25:58.295+0000] {taskinstance.py:1159} INFO - Dependencies all met for dep_context=non-requeueable deps ti=<TaskInstance: bitcoin_transaction_analysis.scrub_data manual__2024-04-28T17:25:50.549263+00:00 [queued]>
[2024-04-28T17:25:58.303+0000] {taskinstance.py:1159} INFO - Dependencies all met for dep_context=requeueable deps ti=<TaskInstance: bitcoin_transaction_analysis.scrub_data manual__2024-04-28T17:25:50.549263+00:00 [queued]>
[2024-04-28T17:25:58.303+0000] {taskinstance.py:1361} INFO - Starting attempt 1 of 2
[2024-04-28T17:25:58.310+0000] {taskinstance.py:1382} INFO - Executing <Task(PythonOperator): scrub_data> on 2024-04-28 17:25:50.549263+00:00
[2024-04-28T17:25:58.314+0000] {standard_task_runner.py:57} INFO - Started process 279 to run task
[2024-04-28T17:25:58.317+0000] {standard_task_runner.py:84} INFO - Running: ['***', 'tasks', 'run', 'bitcoin_transaction_analysis', 'scrub_data', 'manual__2024-04-28T17:25:50.549263+00:00', '--job-id', '140', '--raw', '--subdir', 'DAGS_FOLDER/bitcoin.py', '--cfg-path', '/tmp/tmpz76nvvqe']
[2024-04-28T17:25:58.319+0000] {standard_task_runner.py:85} INFO - Job 140: Subtask scrub_data
[2024-04-28T17:25:58.422+0000] {task_command.py:416} INFO - Running <TaskInstance: bitcoin_transaction_analysis.scrub_data manual__2024-04-28T17:25:50.549263+00:00 [running]> on host 93821e8db187
[2024-04-28T17:25:58.828+0000] {taskinstance.py:1662} INFO - Exporting env vars: AIRFLOW_CTX_DAG_OWNER='***' AIRFLOW_CTX_DAG_ID='bitcoin_transaction_analysis' AIRFLOW_CTX_TASK_ID='scrub_data' AIRFLOW_CTX_EXECUTION_DATE='2024-04-28T17:25:50.549263+00:00' AIRFLOW_CTX_TRY_NUMBER='1' AIRFLOW_CTX_DAG_RUN_ID='manual__2024-04-28T17:25:50.549263+00:00'
[2024-04-28T17:25:58.831+0000] {taskinstance.py:1937} ERROR - Task failed with exception
Traceback (most recent call last):
  File "/home/airflow/.local/lib/python3.8/site-packages/airflow/operators/python.py", line 192, in execute
    return_value = self.execute_callable()
  File "/home/airflow/.local/lib/python3.8/site-packages/airflow/operators/python.py", line 209, in execute_callable
    return self.python_callable(*self.op_args, **self.op_kwargs)
  File "/opt/airflow/dags/bitcoin.py", line 45, in scrub_data
    df_classes = pd.read_csv(path_classes)
  File "/home/airflow/.local/lib/python3.8/site-packages/pandas/io/parsers/readers.py", line 912, in read_csv
    return _read(filepath_or_buffer, kwds)
  File "/home/airflow/.local/lib/python3.8/site-packages/pandas/io/parsers/readers.py", line 577, in _read
    parser = TextFileReader(filepath_or_buffer, **kwds)
  File "/home/airflow/.local/lib/python3.8/site-packages/pandas/io/parsers/readers.py", line 1407, in __init__
    self._engine = self._make_engine(f, self.engine)
  File "/home/airflow/.local/lib/python3.8/site-packages/pandas/io/parsers/readers.py", line 1661, in _make_engine
    self.handles = get_handle(
  File "/home/airflow/.local/lib/python3.8/site-packages/pandas/io/common.py", line 859, in get_handle
    handle = open(
FileNotFoundError: [Errno 2] No such file or directory: '/opt/airflow/dags/datasets/usable_datasets/elliptic_txs_classes.csv'
[2024-04-28T17:25:58.840+0000] {taskinstance.py:1400} INFO - Marking task as UP_FOR_RETRY. dag_id=bitcoin_transaction_analysis, task_id=scrub_data, execution_date=20240428T172550, start_date=20240428T172558, end_date=20240428T172558
[2024-04-28T17:25:58.848+0000] {standard_task_runner.py:104} ERROR - Failed to execute job 140 for task scrub_data ([Errno 2] No such file or directory: '/opt/airflow/dags/datasets/usable_datasets/elliptic_txs_classes.csv'; 279)
[2024-04-28T17:25:58.869+0000] {local_task_job_runner.py:228} INFO - Task exited with return code 1
[2024-04-28T17:25:58.903+0000] {taskinstance.py:2778} INFO - 0 downstream tasks scheduled from follow-on schedule check
