[2024-05-05T01:11:16.972+0000] {taskinstance.py:1159} INFO - Dependencies all met for dep_context=non-requeueable deps ti=<TaskInstance: bitcoin_transaction_analysis.explore_data manual__2024-05-05T01:10:21.491128+00:00 [queued]>
[2024-05-05T01:11:16.977+0000] {taskinstance.py:1159} INFO - Dependencies all met for dep_context=requeueable deps ti=<TaskInstance: bitcoin_transaction_analysis.explore_data manual__2024-05-05T01:10:21.491128+00:00 [queued]>
[2024-05-05T01:11:16.977+0000] {taskinstance.py:1361} INFO - Starting attempt 1 of 2
[2024-05-05T01:11:16.983+0000] {taskinstance.py:1382} INFO - Executing <Task(PythonOperator): explore_data> on 2024-05-05 01:10:21.491128+00:00
[2024-05-05T01:11:16.988+0000] {standard_task_runner.py:57} INFO - Started process 3130 to run task
[2024-05-05T01:11:16.991+0000] {standard_task_runner.py:84} INFO - Running: ['***', 'tasks', 'run', 'bitcoin_transaction_analysis', 'explore_data', 'manual__2024-05-05T01:10:21.491128+00:00', '--job-id', '195', '--raw', '--subdir', 'DAGS_FOLDER/bitcoin.py', '--cfg-path', '/tmp/tmptogmzih4']
[2024-05-05T01:11:16.995+0000] {standard_task_runner.py:85} INFO - Job 195: Subtask explore_data
[2024-05-05T01:11:17.035+0000] {task_command.py:416} INFO - Running <TaskInstance: bitcoin_transaction_analysis.explore_data manual__2024-05-05T01:10:21.491128+00:00 [running]> on host c967b8493ef9
[2024-05-05T01:11:17.116+0000] {taskinstance.py:1662} INFO - Exporting env vars: AIRFLOW_CTX_DAG_OWNER='***' AIRFLOW_CTX_DAG_ID='bitcoin_transaction_analysis' AIRFLOW_CTX_TASK_ID='explore_data' AIRFLOW_CTX_EXECUTION_DATE='2024-05-05T01:10:21.491128+00:00' AIRFLOW_CTX_TRY_NUMBER='1' AIRFLOW_CTX_DAG_RUN_ID='manual__2024-05-05T01:10:21.491128+00:00'
[2024-05-05T01:11:17.119+0000] {taskinstance.py:1937} ERROR - Task failed with exception
Traceback (most recent call last):
  File "/home/airflow/.local/lib/python3.8/site-packages/airflow/operators/python.py", line 192, in execute
    return_value = self.execute_callable()
  File "/home/airflow/.local/lib/python3.8/site-packages/airflow/operators/python.py", line 209, in execute_callable
    return self.python_callable(*self.op_args, **self.op_kwargs)
  File "/opt/airflow/dags/bitcoin.py", line 80, in explore_data
    df_merged = pd.read_csv(path_merged)
  File "/home/airflow/.local/lib/python3.8/site-packages/pandas/io/parsers/readers.py", line 912, in read_csv
    return _read(filepath_or_buffer, kwds)
  File "/home/airflow/.local/lib/python3.8/site-packages/pandas/io/parsers/readers.py", line 577, in _read
    parser = TextFileReader(filepath_or_buffer, **kwds)
  File "/home/airflow/.local/lib/python3.8/site-packages/pandas/io/parsers/readers.py", line 1407, in __init__
    self._engine = self._make_engine(f, self.engine)
  File "/home/airflow/.local/lib/python3.8/site-packages/pandas/io/parsers/readers.py", line 1661, in _make_engine
    self.handles = get_handle(
  File "/home/airflow/.local/lib/python3.8/site-packages/pandas/io/common.py", line 859, in get_handle
    handle = open(
FileNotFoundError: [Errno 2] No such file or directory: '/opt/airflow/dags/datasets/cleaned_datasets/merged_dataset.csv'
[2024-05-05T01:11:17.129+0000] {taskinstance.py:1400} INFO - Marking task as UP_FOR_RETRY. dag_id=bitcoin_transaction_analysis, task_id=explore_data, execution_date=20240505T011021, start_date=20240505T011116, end_date=20240505T011117
[2024-05-05T01:11:17.137+0000] {standard_task_runner.py:104} ERROR - Failed to execute job 195 for task explore_data ([Errno 2] No such file or directory: '/opt/airflow/dags/datasets/cleaned_datasets/merged_dataset.csv'; 3130)
[2024-05-05T01:11:17.173+0000] {local_task_job_runner.py:228} INFO - Task exited with return code 1
[2024-05-05T01:11:17.191+0000] {taskinstance.py:2778} INFO - 0 downstream tasks scheduled from follow-on schedule check
