[2024-05-21T17:08:36.079+0000] {taskinstance.py:1159} INFO - Dependencies all met for dep_context=non-requeueable deps ti=<TaskInstance: fraud_detection.load_and_prepare_data manual__2024-05-21T17:08:22.803094+00:00 [queued]>
[2024-05-21T17:08:36.099+0000] {taskinstance.py:1159} INFO - Dependencies all met for dep_context=requeueable deps ti=<TaskInstance: fraud_detection.load_and_prepare_data manual__2024-05-21T17:08:22.803094+00:00 [queued]>
[2024-05-21T17:08:36.100+0000] {taskinstance.py:1361} INFO - Starting attempt 1 of 2
[2024-05-21T17:08:36.116+0000] {taskinstance.py:1382} INFO - Executing <Task(PythonOperator): load_and_prepare_data> on 2024-05-21 17:08:22.803094+00:00
[2024-05-21T17:08:36.149+0000] {standard_task_runner.py:57} INFO - Started process 290 to run task
[2024-05-21T17:08:36.157+0000] {standard_task_runner.py:84} INFO - Running: ['***', 'tasks', 'run', 'fraud_detection', 'load_and_prepare_data', 'manual__2024-05-21T17:08:22.803094+00:00', '--job-id', '346', '--raw', '--subdir', 'DAGS_FOLDER/fraud.py', '--cfg-path', '/tmp/tmpp15rqcca']
[2024-05-21T17:08:36.162+0000] {standard_task_runner.py:85} INFO - Job 346: Subtask load_and_prepare_data
[2024-05-21T17:08:36.251+0000] {task_command.py:416} INFO - Running <TaskInstance: fraud_detection.load_and_prepare_data manual__2024-05-21T17:08:22.803094+00:00 [running]> on host 3048aab90605
[2024-05-21T17:08:36.341+0000] {taskinstance.py:1662} INFO - Exporting env vars: AIRFLOW_CTX_DAG_OWNER='***' AIRFLOW_CTX_DAG_ID='fraud_detection' AIRFLOW_CTX_TASK_ID='load_and_prepare_data' AIRFLOW_CTX_EXECUTION_DATE='2024-05-21T17:08:22.803094+00:00' AIRFLOW_CTX_TRY_NUMBER='1' AIRFLOW_CTX_DAG_RUN_ID='manual__2024-05-21T17:08:22.803094+00:00'
[2024-05-21T17:08:36.347+0000] {taskinstance.py:1937} ERROR - Task failed with exception
Traceback (most recent call last):
  File "/home/airflow/.local/lib/python3.8/site-packages/airflow/operators/python.py", line 192, in execute
    return_value = self.execute_callable()
  File "/home/airflow/.local/lib/python3.8/site-packages/airflow/operators/python.py", line 209, in execute_callable
    return self.python_callable(*self.op_args, **self.op_kwargs)
  File "/opt/airflow/dags/fraud.py", line 38, in load_and_prepare_data
    data = pd.read_csv(file_path)
  File "/home/airflow/.local/lib/python3.8/site-packages/pandas/io/parsers/readers.py", line 912, in read_csv
    return _read(filepath_or_buffer, kwds)
  File "/home/airflow/.local/lib/python3.8/site-packages/pandas/io/parsers/readers.py", line 577, in _read
    parser = TextFileReader(filepath_or_buffer, **kwds)
  File "/home/airflow/.local/lib/python3.8/site-packages/pandas/io/parsers/readers.py", line 1407, in __init__
    self._engine = self._make_engine(f, self.engine)
  File "/home/airflow/.local/lib/python3.8/site-packages/pandas/io/parsers/readers.py", line 1661, in _make_engine
    self.handles = get_handle(
  File "/home/airflow/.local/lib/python3.8/site-packages/pandas/io/common.py", line 859, in get_handle
    handle = open(
FileNotFoundError: [Errno 2] No such file or directory: 'path_to_your_csv/out.csv'
[2024-05-21T17:08:36.361+0000] {taskinstance.py:1400} INFO - Marking task as UP_FOR_RETRY. dag_id=fraud_detection, task_id=load_and_prepare_data, execution_date=20240521T170822, start_date=20240521T170836, end_date=20240521T170836
[2024-05-21T17:08:36.372+0000] {standard_task_runner.py:104} ERROR - Failed to execute job 346 for task load_and_prepare_data ([Errno 2] No such file or directory: 'path_to_your_csv/out.csv'; 290)
[2024-05-21T17:08:36.417+0000] {local_task_job_runner.py:228} INFO - Task exited with return code 1
[2024-05-21T17:08:36.441+0000] {taskinstance.py:2778} INFO - 0 downstream tasks scheduled from follow-on schedule check
