[2024-04-28T17:15:31.072+0000] {taskinstance.py:1159} INFO - Dependencies all met for dep_context=non-requeueable deps ti=<TaskInstance: bitcoin_transaction_analysis.obtain_data manual__2024-04-28T17:10:27.072967+00:00 [queued]>
[2024-04-28T17:15:31.078+0000] {taskinstance.py:1159} INFO - Dependencies all met for dep_context=requeueable deps ti=<TaskInstance: bitcoin_transaction_analysis.obtain_data manual__2024-04-28T17:10:27.072967+00:00 [queued]>
[2024-04-28T17:15:31.078+0000] {taskinstance.py:1361} INFO - Starting attempt 2 of 2
[2024-04-28T17:15:31.087+0000] {taskinstance.py:1382} INFO - Executing <Task(PythonOperator): obtain_data> on 2024-04-28 17:10:27.072967+00:00
[2024-04-28T17:15:31.093+0000] {standard_task_runner.py:57} INFO - Started process 101 to run task
[2024-04-28T17:15:31.096+0000] {standard_task_runner.py:84} INFO - Running: ['***', 'tasks', 'run', 'bitcoin_transaction_analysis', 'obtain_data', 'manual__2024-04-28T17:10:27.072967+00:00', '--job-id', '134', '--raw', '--subdir', 'DAGS_FOLDER/bitcoin.py', '--cfg-path', '/tmp/tmpbvuxkds9']
[2024-04-28T17:15:31.102+0000] {standard_task_runner.py:85} INFO - Job 134: Subtask obtain_data
[2024-04-28T17:15:31.156+0000] {task_command.py:416} INFO - Running <TaskInstance: bitcoin_transaction_analysis.obtain_data manual__2024-04-28T17:10:27.072967+00:00 [running]> on host 93821e8db187
[2024-04-28T17:15:31.487+0000] {taskinstance.py:1662} INFO - Exporting env vars: AIRFLOW_CTX_DAG_OWNER='***' AIRFLOW_CTX_DAG_ID='bitcoin_transaction_analysis' AIRFLOW_CTX_TASK_ID='obtain_data' AIRFLOW_CTX_EXECUTION_DATE='2024-04-28T17:10:27.072967+00:00' AIRFLOW_CTX_TRY_NUMBER='2' AIRFLOW_CTX_DAG_RUN_ID='manual__2024-04-28T17:10:27.072967+00:00'
[2024-04-28T17:15:31.488+0000] {taskinstance.py:1937} ERROR - Task failed with exception
Traceback (most recent call last):
  File "/home/airflow/.local/lib/python3.8/site-packages/airflow/operators/python.py", line 192, in execute
    return_value = self.execute_callable()
  File "/home/airflow/.local/lib/python3.8/site-packages/airflow/operators/python.py", line 209, in execute_callable
    return self.python_callable(*self.op_args, **self.op_kwargs)
  File "/opt/airflow/dags/bitcoin.py", line 32, in obtain_data
    with zipfile.ZipFile('$DATASET_PATH/bitcoin.zip', 'r') as z:
  File "/usr/local/lib/python3.8/zipfile.py", line 1251, in __init__
    self.fp = io.open(file, filemode)
FileNotFoundError: [Errno 2] No such file or directory: '$DATASET_PATH/bitcoin.zip'
[2024-04-28T17:15:31.496+0000] {taskinstance.py:1400} INFO - Marking task as FAILED. dag_id=bitcoin_transaction_analysis, task_id=obtain_data, execution_date=20240428T171027, start_date=20240428T171531, end_date=20240428T171531
[2024-04-28T17:15:31.507+0000] {standard_task_runner.py:104} ERROR - Failed to execute job 134 for task obtain_data ([Errno 2] No such file or directory: '$DATASET_PATH/bitcoin.zip'; 101)
[2024-04-28T17:15:31.531+0000] {local_task_job_runner.py:228} INFO - Task exited with return code 1
[2024-04-28T17:15:31.686+0000] {taskinstance.py:2778} INFO - 0 downstream tasks scheduled from follow-on schedule check
