[2024-04-28T17:10:28.693+0000] {taskinstance.py:1159} INFO - Dependencies all met for dep_context=non-requeueable deps ti=<TaskInstance: bitcoin_transaction_analysis.obtain_data manual__2024-04-28T17:10:27.072967+00:00 [queued]>
[2024-04-28T17:10:28.700+0000] {taskinstance.py:1159} INFO - Dependencies all met for dep_context=requeueable deps ti=<TaskInstance: bitcoin_transaction_analysis.obtain_data manual__2024-04-28T17:10:27.072967+00:00 [queued]>
[2024-04-28T17:10:28.700+0000] {taskinstance.py:1361} INFO - Starting attempt 1 of 2
[2024-04-28T17:10:28.708+0000] {taskinstance.py:1382} INFO - Executing <Task(PythonOperator): obtain_data> on 2024-04-28 17:10:27.072967+00:00
[2024-04-28T17:10:28.711+0000] {standard_task_runner.py:57} INFO - Started process 136 to run task
[2024-04-28T17:10:28.713+0000] {standard_task_runner.py:84} INFO - Running: ['***', 'tasks', 'run', 'bitcoin_transaction_analysis', 'obtain_data', 'manual__2024-04-28T17:10:27.072967+00:00', '--job-id', '130', '--raw', '--subdir', 'DAGS_FOLDER/.ipynb_checkpoints/bitcoin-checkpoint.py', '--cfg-path', '/tmp/tmpbaijzh1o']
[2024-04-28T17:10:28.716+0000] {standard_task_runner.py:85} INFO - Job 130: Subtask obtain_data
[2024-04-28T17:10:28.751+0000] {task_command.py:416} INFO - Running <TaskInstance: bitcoin_transaction_analysis.obtain_data manual__2024-04-28T17:10:27.072967+00:00 [running]> on host 380dfa8bbbe1
[2024-04-28T17:10:29.057+0000] {taskinstance.py:1662} INFO - Exporting env vars: AIRFLOW_CTX_DAG_OWNER='***' AIRFLOW_CTX_DAG_ID='bitcoin_transaction_analysis' AIRFLOW_CTX_TASK_ID='obtain_data' AIRFLOW_CTX_EXECUTION_DATE='2024-04-28T17:10:27.072967+00:00' AIRFLOW_CTX_TRY_NUMBER='1' AIRFLOW_CTX_DAG_RUN_ID='manual__2024-04-28T17:10:27.072967+00:00'
[2024-04-28T17:10:29.058+0000] {taskinstance.py:1937} ERROR - Task failed with exception
Traceback (most recent call last):
  File "/home/airflow/.local/lib/python3.8/site-packages/airflow/operators/python.py", line 192, in execute
    return_value = self.execute_callable()
  File "/home/airflow/.local/lib/python3.8/site-packages/airflow/operators/python.py", line 209, in execute_callable
    return self.python_callable(*self.op_args, **self.op_kwargs)
  File "/opt/airflow/dags/.ipynb_checkpoints/bitcoin-checkpoint.py", line 32, in obtain_data
    with zipfile.ZipFile('$DATASET_PATH/bitcoin.zip', 'r') as z:
  File "/usr/local/lib/python3.8/zipfile.py", line 1251, in __init__
    self.fp = io.open(file, filemode)
FileNotFoundError: [Errno 2] No such file or directory: '$DATASET_PATH/bitcoin.zip'
[2024-04-28T17:10:29.066+0000] {taskinstance.py:1400} INFO - Marking task as UP_FOR_RETRY. dag_id=bitcoin_transaction_analysis, task_id=obtain_data, execution_date=20240428T171027, start_date=20240428T171028, end_date=20240428T171029
[2024-04-28T17:10:29.074+0000] {standard_task_runner.py:104} ERROR - Failed to execute job 130 for task obtain_data ([Errno 2] No such file or directory: '$DATASET_PATH/bitcoin.zip'; 136)
[2024-04-28T17:10:29.099+0000] {local_task_job_runner.py:228} INFO - Task exited with return code 1
[2024-04-28T17:10:29.116+0000] {taskinstance.py:2778} INFO - 0 downstream tasks scheduled from follow-on schedule check
