[2023-12-22T09:14:17.119+0000] {taskinstance.py:1159} INFO - Dependencies all met for dep_context=non-requeueable deps ti=<TaskInstance: dd_mssql_snapshot.generate_date_strings manual__2023-12-22T09:12:30.494042+00:00 [queued]>
[2023-12-22T09:14:17.126+0000] {taskinstance.py:1159} INFO - Dependencies all met for dep_context=requeueable deps ti=<TaskInstance: dd_mssql_snapshot.generate_date_strings manual__2023-12-22T09:12:30.494042+00:00 [queued]>
[2023-12-22T09:14:17.126+0000] {taskinstance.py:1361} INFO - Starting attempt 3 of 4
[2023-12-22T09:14:17.133+0000] {taskinstance.py:1382} INFO - Executing <Task(_PythonDecoratedOperator): generate_date_strings> on 2023-12-22 09:12:30.494042+00:00
[2023-12-22T09:14:17.138+0000] {standard_task_runner.py:57} INFO - Started process 223 to run task
[2023-12-22T09:14:17.141+0000] {standard_task_runner.py:84} INFO - Running: ['***', 'tasks', 'run', 'dd_mssql_snapshot', 'generate_date_strings', 'manual__2023-12-22T09:12:30.494042+00:00', '--job-id', '12', '--raw', '--subdir', 'DAGS_FOLDER/test-date.py', '--cfg-path', '/tmp/tmppe4_5hdp']
[2023-12-22T09:14:17.142+0000] {standard_task_runner.py:85} INFO - Job 12: Subtask generate_date_strings
[2023-12-22T09:14:17.208+0000] {task_command.py:416} INFO - Running <TaskInstance: dd_mssql_snapshot.generate_date_strings manual__2023-12-22T09:12:30.494042+00:00 [running]> on host 90263e0a625e
[2023-12-22T09:14:17.348+0000] {taskinstance.py:1662} INFO - Exporting env vars: AIRFLOW_CTX_DAG_OWNER='***' AIRFLOW_CTX_DAG_ID='dd_mssql_snapshot' AIRFLOW_CTX_TASK_ID='generate_date_strings' AIRFLOW_CTX_EXECUTION_DATE='2023-12-22T09:12:30.494042+00:00' AIRFLOW_CTX_TRY_NUMBER='3' AIRFLOW_CTX_DAG_RUN_ID='manual__2023-12-22T09:12:30.494042+00:00'
[2023-12-22T09:14:17.350+0000] {taskinstance.py:1937} ERROR - Task failed with exception
Traceback (most recent call last):
  File "/home/airflow/.local/lib/python3.8/site-packages/airflow/decorators/base.py", line 221, in execute
    return_value = super().execute(context)
  File "/home/airflow/.local/lib/python3.8/site-packages/airflow/operators/python.py", line 192, in execute
    return_value = self.execute_callable()
  File "/home/airflow/.local/lib/python3.8/site-packages/airflow/operators/python.py", line 209, in execute_callable
    return self.python_callable(*self.op_args, **self.op_kwargs)
  File "/opt/airflow/dags/test-date.py", line 42, in generate_date_strings
    current_time = ed.replace(second=0, microsecond=0, minute=0)
AttributeError: 'TaskInstance' object has no attribute 'replace'
[2023-12-22T09:14:17.359+0000] {taskinstance.py:1400} INFO - Marking task as UP_FOR_RETRY. dag_id=dd_mssql_snapshot, task_id=generate_date_strings, execution_date=20231222T091230, start_date=20231222T091417, end_date=20231222T091417
[2023-12-22T09:14:17.369+0000] {standard_task_runner.py:104} ERROR - Failed to execute job 12 for task generate_date_strings ('TaskInstance' object has no attribute 'replace'; 223)
[2023-12-22T09:14:17.401+0000] {local_task_job_runner.py:228} INFO - Task exited with return code 1
[2023-12-22T09:14:17.416+0000] {taskinstance.py:2778} INFO - 0 downstream tasks scheduled from follow-on schedule check
