[2024-05-22T00:48:56.597+0000] {taskinstance.py:1159} INFO - Dependencies all met for dep_context=non-requeueable deps ti=<TaskInstance: fraud_bitcoin.train_xgboost scheduled__2024-05-21T00:00:00+00:00 [queued]>
[2024-05-22T00:48:56.610+0000] {taskinstance.py:1159} INFO - Dependencies all met for dep_context=requeueable deps ti=<TaskInstance: fraud_bitcoin.train_xgboost scheduled__2024-05-21T00:00:00+00:00 [queued]>
[2024-05-22T00:48:56.611+0000] {taskinstance.py:1361} INFO - Starting attempt 6 of 6
[2024-05-22T00:48:56.627+0000] {taskinstance.py:1382} INFO - Executing <Task(PythonOperator): train_xgboost> on 2024-05-21 00:00:00+00:00
[2024-05-22T00:48:56.670+0000] {standard_task_runner.py:57} INFO - Started process 4541 to run task
[2024-05-22T00:48:56.693+0000] {standard_task_runner.py:84} INFO - Running: ['***', 'tasks', 'run', 'fraud_bitcoin', 'train_xgboost', 'scheduled__2024-05-21T00:00:00+00:00', '--job-id', '403', '--raw', '--subdir', 'DAGS_FOLDER/fraud.py', '--cfg-path', '/tmp/tmp0fhmdoni']
[2024-05-22T00:48:56.722+0000] {standard_task_runner.py:85} INFO - Job 403: Subtask train_xgboost
[2024-05-22T00:48:57.822+0000] {task_command.py:416} INFO - Running <TaskInstance: fraud_bitcoin.train_xgboost scheduled__2024-05-21T00:00:00+00:00 [running]> on host 66abfe055500
[2024-05-22T00:48:58.281+0000] {taskinstance.py:1662} INFO - Exporting env vars: AIRFLOW_CTX_DAG_OWNER='***' AIRFLOW_CTX_DAG_ID='fraud_bitcoin' AIRFLOW_CTX_TASK_ID='train_xgboost' AIRFLOW_CTX_EXECUTION_DATE='2024-05-21T00:00:00+00:00' AIRFLOW_CTX_TRY_NUMBER='6' AIRFLOW_CTX_DAG_RUN_ID='scheduled__2024-05-21T00:00:00+00:00'
[2024-05-22T00:48:58.440+0000] {taskinstance.py:1937} ERROR - Task failed with exception
Traceback (most recent call last):
  File "/home/airflow/.local/lib/python3.8/site-packages/airflow/operators/python.py", line 192, in execute
    return_value = self.execute_callable()
  File "/home/airflow/.local/lib/python3.8/site-packages/airflow/operators/python.py", line 209, in execute_callable
    return self.python_callable(*self.op_args, **self.op_kwargs)
  File "/opt/airflow/dags/fraud.py", line 167, in train_xgboost
    xgb_model.fit(X_significant_train, y_train)
  File "/home/airflow/.local/lib/python3.8/site-packages/xgboost/core.py", line 730, in inner_f
    return func(**kwargs)
  File "/home/airflow/.local/lib/python3.8/site-packages/xgboost/sklearn.py", line 1471, in fit
    raise ValueError(
ValueError: Invalid classes inferred from unique values of `y`.  Expected: [0 1], got [1 2]
[2024-05-22T00:48:58.476+0000] {taskinstance.py:1400} INFO - Marking task as FAILED. dag_id=fraud_bitcoin, task_id=train_xgboost, execution_date=20240521T000000, start_date=20240522T004856, end_date=20240522T004858
[2024-05-22T00:48:58.507+0000] {standard_task_runner.py:104} ERROR - Failed to execute job 403 for task train_xgboost (Invalid classes inferred from unique values of `y`.  Expected: [0 1], got [1 2]; 4541)
[2024-05-22T00:48:58.626+0000] {local_task_job_runner.py:228} INFO - Task exited with return code 1
[2024-05-22T00:48:58.752+0000] {taskinstance.py:2778} INFO - 0 downstream tasks scheduled from follow-on schedule check
