[2024-05-22T00:28:37.540+0000] {taskinstance.py:1159} INFO - Dependencies all met for dep_context=non-requeueable deps ti=<TaskInstance: fraud_bitcoin.train_xgboost scheduled__2024-05-21T00:00:00+00:00 [queued]>
[2024-05-22T00:28:37.554+0000] {taskinstance.py:1159} INFO - Dependencies all met for dep_context=requeueable deps ti=<TaskInstance: fraud_bitcoin.train_xgboost scheduled__2024-05-21T00:00:00+00:00 [queued]>
[2024-05-22T00:28:37.555+0000] {taskinstance.py:1361} INFO - Starting attempt 3 of 4
[2024-05-22T00:28:37.592+0000] {taskinstance.py:1382} INFO - Executing <Task(PythonOperator): train_xgboost> on 2024-05-21 00:00:00+00:00
[2024-05-22T00:28:37.665+0000] {standard_task_runner.py:57} INFO - Started process 4024 to run task
[2024-05-22T00:28:37.676+0000] {standard_task_runner.py:84} INFO - Running: ['***', 'tasks', 'run', 'fraud_bitcoin', 'train_xgboost', 'scheduled__2024-05-21T00:00:00+00:00', '--job-id', '388', '--raw', '--subdir', 'DAGS_FOLDER/fraud.py', '--cfg-path', '/tmp/tmp9x7l6qfk']
[2024-05-22T00:28:37.685+0000] {standard_task_runner.py:85} INFO - Job 388: Subtask train_xgboost
[2024-05-22T00:28:37.836+0000] {task_command.py:416} INFO - Running <TaskInstance: fraud_bitcoin.train_xgboost scheduled__2024-05-21T00:00:00+00:00 [running]> on host 66abfe055500
[2024-05-22T00:28:37.993+0000] {taskinstance.py:1662} INFO - Exporting env vars: AIRFLOW_CTX_DAG_OWNER='***' AIRFLOW_CTX_DAG_ID='fraud_bitcoin' AIRFLOW_CTX_TASK_ID='train_xgboost' AIRFLOW_CTX_EXECUTION_DATE='2024-05-21T00:00:00+00:00' AIRFLOW_CTX_TRY_NUMBER='3' AIRFLOW_CTX_DAG_RUN_ID='scheduled__2024-05-21T00:00:00+00:00'
[2024-05-22T00:28:38.085+0000] {taskinstance.py:1937} ERROR - Task failed with exception
Traceback (most recent call last):
  File "/home/airflow/.local/lib/python3.8/site-packages/airflow/operators/python.py", line 192, in execute
    return_value = self.execute_callable()
  File "/home/airflow/.local/lib/python3.8/site-packages/airflow/operators/python.py", line 209, in execute_callable
    return self.python_callable(*self.op_args, **self.op_kwargs)
  File "/opt/airflow/dags/fraud.py", line 124, in train_xgboost
    xgb_model.fit(X_significant_train, y_train)
  File "/home/airflow/.local/lib/python3.8/site-packages/xgboost/core.py", line 730, in inner_f
    return func(**kwargs)
  File "/home/airflow/.local/lib/python3.8/site-packages/xgboost/sklearn.py", line 1471, in fit
    raise ValueError(
ValueError: Invalid classes inferred from unique values of `y`.  Expected: [0 1], got [1 2]
[2024-05-22T00:28:38.107+0000] {taskinstance.py:1400} INFO - Marking task as UP_FOR_RETRY. dag_id=fraud_bitcoin, task_id=train_xgboost, execution_date=20240521T000000, start_date=20240522T002837, end_date=20240522T002838
[2024-05-22T00:28:38.185+0000] {standard_task_runner.py:104} ERROR - Failed to execute job 388 for task train_xgboost (Invalid classes inferred from unique values of `y`.  Expected: [0 1], got [1 2]; 4024)
[2024-05-22T00:28:38.224+0000] {local_task_job_runner.py:228} INFO - Task exited with return code 1
[2024-05-22T00:28:38.313+0000] {taskinstance.py:2778} INFO - 0 downstream tasks scheduled from follow-on schedule check
