[2024-05-22T00:28:37.508+0000] {taskinstance.py:1159} INFO - Dependencies all met for dep_context=non-requeueable deps ti=<TaskInstance: fraud_bitcoin.train_random_forest scheduled__2024-05-21T00:00:00+00:00 [queued]>
[2024-05-22T00:28:37.534+0000] {taskinstance.py:1159} INFO - Dependencies all met for dep_context=requeueable deps ti=<TaskInstance: fraud_bitcoin.train_random_forest scheduled__2024-05-21T00:00:00+00:00 [queued]>
[2024-05-22T00:28:37.535+0000] {taskinstance.py:1361} INFO - Starting attempt 3 of 4
[2024-05-22T00:28:37.556+0000] {taskinstance.py:1382} INFO - Executing <Task(PythonOperator): train_random_forest> on 2024-05-21 00:00:00+00:00
[2024-05-22T00:28:37.605+0000] {standard_task_runner.py:57} INFO - Started process 4022 to run task
[2024-05-22T00:28:37.640+0000] {standard_task_runner.py:84} INFO - Running: ['***', 'tasks', 'run', 'fraud_bitcoin', 'train_random_forest', 'scheduled__2024-05-21T00:00:00+00:00', '--job-id', '387', '--raw', '--subdir', 'DAGS_FOLDER/fraud.py', '--cfg-path', '/tmp/tmpntjqv9q3']
[2024-05-22T00:28:37.657+0000] {standard_task_runner.py:85} INFO - Job 387: Subtask train_random_forest
[2024-05-22T00:28:37.797+0000] {task_command.py:416} INFO - Running <TaskInstance: fraud_bitcoin.train_random_forest scheduled__2024-05-21T00:00:00+00:00 [running]> on host 66abfe055500
[2024-05-22T00:28:37.954+0000] {taskinstance.py:1662} INFO - Exporting env vars: AIRFLOW_CTX_DAG_OWNER='***' AIRFLOW_CTX_DAG_ID='fraud_bitcoin' AIRFLOW_CTX_TASK_ID='train_random_forest' AIRFLOW_CTX_EXECUTION_DATE='2024-05-21T00:00:00+00:00' AIRFLOW_CTX_TRY_NUMBER='3' AIRFLOW_CTX_DAG_RUN_ID='scheduled__2024-05-21T00:00:00+00:00'
[2024-05-22T00:28:38.066+0000] {taskinstance.py:1937} ERROR - Task failed with exception
Traceback (most recent call last):
  File "/home/airflow/.local/lib/python3.8/site-packages/airflow/operators/python.py", line 192, in execute
    return_value = self.execute_callable()
  File "/home/airflow/.local/lib/python3.8/site-packages/airflow/operators/python.py", line 209, in execute_callable
    return self.python_callable(*self.op_args, **self.op_kwargs)
  File "/opt/airflow/dags/fraud.py", line 109, in train_random_forest
    rf_model.fit(X_significant_train, y_train)
  File "/home/airflow/.local/lib/python3.8/site-packages/sklearn/base.py", line 1152, in wrapper
    return fit_method(estimator, *args, **kwargs)
  File "/home/airflow/.local/lib/python3.8/site-packages/sklearn/ensemble/_forest.py", line 348, in fit
    X, y = self._validate_data(
  File "/home/airflow/.local/lib/python3.8/site-packages/sklearn/base.py", line 622, in _validate_data
    X, y = check_X_y(X, y, **check_params)
  File "/home/airflow/.local/lib/python3.8/site-packages/sklearn/utils/validation.py", line 1146, in check_X_y
    X = check_array(
  File "/home/airflow/.local/lib/python3.8/site-packages/sklearn/utils/validation.py", line 976, in check_array
    raise ValueError(
ValueError: Found array with 0 feature(s) (shape=(944, 0)) while a minimum of 1 is required by RandomForestClassifier.
[2024-05-22T00:28:38.086+0000] {taskinstance.py:1400} INFO - Marking task as UP_FOR_RETRY. dag_id=fraud_bitcoin, task_id=train_random_forest, execution_date=20240521T000000, start_date=20240522T002837, end_date=20240522T002838
[2024-05-22T00:28:38.102+0000] {standard_task_runner.py:104} ERROR - Failed to execute job 387 for task train_random_forest (Found array with 0 feature(s) (shape=(944, 0)) while a minimum of 1 is required by RandomForestClassifier.; 4022)
[2024-05-22T00:28:38.189+0000] {local_task_job_runner.py:228} INFO - Task exited with return code 1
[2024-05-22T00:28:38.258+0000] {taskinstance.py:2778} INFO - 0 downstream tasks scheduled from follow-on schedule check
