[2023-12-26T08:40:38.733+0000] {taskinstance.py:1159} INFO - Dependencies all met for dep_context=non-requeueable deps ti=<TaskInstance: dd_mssql_snapshot.generate_date_strings manual__2023-12-26T08:19:56.938872+00:00 [queued]>
[2023-12-26T08:40:38.739+0000] {taskinstance.py:1159} INFO - Dependencies all met for dep_context=requeueable deps ti=<TaskInstance: dd_mssql_snapshot.generate_date_strings manual__2023-12-26T08:19:56.938872+00:00 [queued]>
[2023-12-26T08:40:38.739+0000] {taskinstance.py:1361} INFO - Starting attempt 17 of 18
[2023-12-26T08:40:38.745+0000] {taskinstance.py:1382} INFO - Executing <Task(_PythonDecoratedOperator): generate_date_strings> on 2023-12-26 08:19:56.938872+00:00
[2023-12-26T08:40:38.750+0000] {standard_task_runner.py:57} INFO - Started process 3297 to run task
[2023-12-26T08:40:38.752+0000] {standard_task_runner.py:84} INFO - Running: ['***', 'tasks', 'run', 'dd_mssql_snapshot', 'generate_date_strings', 'manual__2023-12-26T08:19:56.938872+00:00', '--job-id', '61', '--raw', '--subdir', 'DAGS_FOLDER/test-date.py', '--cfg-path', '/tmp/tmp55oek74z']
[2023-12-26T08:40:38.753+0000] {standard_task_runner.py:85} INFO - Job 61: Subtask generate_date_strings
[2023-12-26T08:40:38.799+0000] {task_command.py:416} INFO - Running <TaskInstance: dd_mssql_snapshot.generate_date_strings manual__2023-12-26T08:19:56.938872+00:00 [running]> on host 5837c4e7e133
[2023-12-26T08:40:38.859+0000] {taskinstance.py:1662} INFO - Exporting env vars: AIRFLOW_CTX_DAG_OWNER='***' AIRFLOW_CTX_DAG_ID='dd_mssql_snapshot' AIRFLOW_CTX_TASK_ID='generate_date_strings' AIRFLOW_CTX_EXECUTION_DATE='2023-12-26T08:19:56.938872+00:00' AIRFLOW_CTX_TRY_NUMBER='17' AIRFLOW_CTX_DAG_RUN_ID='manual__2023-12-26T08:19:56.938872+00:00'
[2023-12-26T08:40:38.865+0000] {taskinstance.py:1937} ERROR - Task failed with exception
Traceback (most recent call last):
  File "/home/airflow/.local/lib/python3.8/site-packages/airflow/decorators/base.py", line 221, in execute
    return_value = super().execute(context)
  File "/home/airflow/.local/lib/python3.8/site-packages/airflow/operators/python.py", line 192, in execute
    return_value = self.execute_callable()
  File "/home/airflow/.local/lib/python3.8/site-packages/airflow/operators/python.py", line 209, in execute_callable
    return self.python_callable(*self.op_args, **self.op_kwargs)
  File "/opt/airflow/dags/test-date.py", line 48, in generate_date_strings
    d = datetime.strptime(t, "%Y-%m-%dT%H:%M:%S.%f")
TypeError: strptime() argument 1 must be str, not datetime.datetime
[2023-12-26T08:40:38.874+0000] {taskinstance.py:1400} INFO - Marking task as UP_FOR_RETRY. dag_id=dd_mssql_snapshot, task_id=generate_date_strings, execution_date=20231226T081956, start_date=20231226T084038, end_date=20231226T084038
[2023-12-26T08:40:38.881+0000] {standard_task_runner.py:104} ERROR - Failed to execute job 61 for task generate_date_strings (strptime() argument 1 must be str, not datetime.datetime; 3297)
[2023-12-26T08:40:38.891+0000] {local_task_job_runner.py:228} INFO - Task exited with return code 1
[2023-12-26T08:40:38.905+0000] {taskinstance.py:2778} INFO - 0 downstream tasks scheduled from follow-on schedule check
